Workbook

Sheet Cover
B1: SHOPIFY INC. (SHOP) — INVESTMENT BANKING ANALYSIS
B2: Prepared by: Vatsal Chavda | Honours BCom (Finance), Seneca Polytechnic | January 2026 | Independent Research
B4: COMPANY OVERVIEW
B5: Company | C5: Shopify Inc.
B6: Ticker / Exchange | C6: SHOP — NYSE / TSX
B7: Sector / Industry | C7: Technology / E-Commerce Infrastructure
B8: Fiscal Year End | C8: December 31
B9: Reporting Currency | C9: USD (millions)
B10: Analysis Date | C10: 46082
B11: Analyst | C11: Vatsal Chavda
B13: ANALYSIS COMPONENTS
B14: 1. Financial Statements | C14: Historical Income Statement, Balance Sheet & Cash Flow (FY2021–FY2024)
B15: 2. DCF Valuation | C15: 5-Year FCF Projection, WACC, Terminal Value, Implied Share Price
B16: 3. Comparable Company Analysis | C16: EV/Revenue, EV/EBITDA, P/E vs. SaaS/E-Commerce Peers
B17: 4. Precedent Transactions | C17: Selected E-Commerce & Fintech M&A Transactions
B18: 5. M&A Strategic Analysis | C18: Acquisition Target, Synergy Model, Accretion/Dilution
B19: 6. Capital Structure | C19: Debt Capacity, Credit Metrics, Financing Recommendation
B20: 7. Investment Summary | C20: Price Target, Rating, Key Risks & Catalysts
B22: KEY OUTPUTS (Live Links)
B23: Implied Share Price (DCF) | C23: ='DCF Model'!C77 -> 36.808
B24: Current Share Price | C24: ='DCF Model'!C78 -> 87.2
B25: Upside / (Downside) | C25: ='DCF Model'!C79 -> -0.57788991
B26: Investment Rating | C26: ='Inv. Summary'!C5 -> SELL
B27: EV/NTM Revenue (Comps Median) | C27: =Comps!E17 -> 4.3820225
B28: Implied EV (Comps) | C28: =Comps!E22 -> 49786.392
B29: Accretion / (Dilution) — M&A | C29: ='M&A Analysis'!C42 -> -0.16219237
B31: DISCLAIMER: This analysis is an independent project prepared for educational purposes created by Vatsal Chavda . All financial data is sourced from public filings (Shopify 10-K/20-F, SEC EDGAR). This does not constitute investment advice.

Sheet Financials
B1: SHOPIFY INC. — HISTORICAL FINANCIAL STATEMENTS | FY2021–FY2024 (USD $mm)
B2: Source: Shopify Inc. Annual Reports (20-F), SEC EDGAR — https://www.sec.gov/cgi-bin/browse-edgar?action=getcompany&CIK=SHOP
B4: Line Item | C4: FY2021 | D4: FY2022 | E4: FY2023 | F4: FY2024
B5: INCOME STATEMENT
B6: Merchant Solutions Revenue | C6: 2568.8 | D6: 3909.7 | E6: 5155.6 | F6: 7069 | H6: Source: Shopify 20-F FY2024, Note 3 Revenue Disaggregation, https://investors.shopify.com
B7: Subscription Solutions Revenue | C7: 886 | D7: 1077.5 | E7: 1479.9 | F7: 2168 | H7: Source: Shopify 20-F FY2024, Note 3 Revenue Disaggregation
B8: Total Revenue | C8: =C6+C7 -> 3454.8 | D8: =D6+D7 -> 4987.2 | E8: =E6+E7 -> 6635.5 | F8: =F6+F7 -> 9237 | H8: Derived
B9: Cost of Revenue — Merchant | C9: 1717 | D9: 2685.4 | E9: 3484.6 | F9: 4651 | H9: Source: Shopify 20-F FY2024, Consolidated Statements of Operations
B10: Cost of Revenue — Subscription | C10: 167.4 | D10: 224.5 | E10: 276.4 | F10: 378 | H10: Source: Shopify 20-F FY2024
B11: Total Cost of Revenue | C11: =C9+C10 -> 1884.4 | D11: =D9+D10 -> 2909.9 | E11: =E9+E10 -> 3761 | F11: =F9+F10 -> 5029 | H11: Derived
B12: Gross Profit | C12: =C8-C11 -> 1570.4 | D12: =D8-D11 -> 2077.3 | E12: =E8-E11 -> 2874.5 | F12: =F8-F11 -> 4208 | H12: Derived
B13: Gross Margin % | C13: =C12/C8 -> 0.45455598 | D13: =D12/D8 -> 0.41652631 | E13: =E12/E8 -> 0.43320021 | F13: =F12/F8 -> 0.45555916 | H13: Derived
B14: Sales & Marketing | C14: 673 | D14: 835.9 | E14: 975 | F14: 1161 | H14: Source: Shopify 20-F FY2024, Operating Expenses
B15: Research & Development | C15: 885.6 | D15: 1196.9 | E15: 1298.6 | F15: 1563 | H15: Source: Shopify 20-F FY2024, Operating Expenses
B16: General & Administrative | C16: 321.1 | D16: 438.8 | E16: 477.3 | F16: 531 | H16: Source: Shopify 20-F FY2024, Operating Expenses
B17: Total Operating Expenses | C17: =C14+C15+C16 -> 1879.7 | D17: =D14+D15+D16 -> 2471.6 | E17: =E14+E15+E16 -> 2750.9 | F17: =F14+F15+F16 -> 3255 | H17: Derived
B18: EBITDA (adj.) | C18: =C12-C17 -> -309.3 | D18: =D12-D17 -> -394.3 | E18: =E12-E17 -> 123.6 | F18: =F12-F17 -> 953 | H18: Derived: Gross Profit less OpEx (excl. D&A)
B19: EBITDA Margin % | C19: =C18/C8 -> -0.089527614 | D19: =D18/D8 -> -0.0790624 | E19: =E18/E8 -> 0.018627082 | F19: =F18/F8 -> 0.10317203 | H19: Derived
B20: Depreciation & Amortization | C20: 63 | D20: 132 | E20: 213 | F20: 280 | H20: Source: Shopify 20-F FY2024, Cash Flow Statement
B21: EBIT | C21: =C18-C20 -> -372.3 | D21: =D18-D20 -> -526.3 | E21: =E18-E20 -> -89.4 | F21: =F18-F20 -> 673 | H21: Derived
B22: Interest & Other Income (net) | C22: 49 | D22: 29 | E22: 122 | F22: 236 | H22: Source: Shopify 20-F FY2024
B23: Pre-Tax Income | C23: =C21+C22 -> -323.3 | D23: =D21+D22 -> -497.3 | E23: =E21+E22 -> 32.6 | F23: =F21+F22 -> 909 | H23: Derived
B24: Income Tax Expense | C24: 8 | D24: 11 | E24: 22 | F24: 53 | H24: Source: Shopify 20-F FY2024
B25: Net Income | C25: =C23-C24 -> -331.3 | D25: =D23-D24 -> -508.3 | E25: =E23-E24 -> 10.6 | F25: =F23-F24 -> 856 | H25: Derived
B26: Net Margin % | C26: =C25/C8 -> -0.095895566 | D26: =D25/D8 -> -0.10192092 | E26: =E25/E8 -> 0.0015974682 | F26: =F25/F8 -> 0.092670781 | H26: Derived
B27: Diluted EPS (USD) | C27: =C25/2778 -> -0.11925846 | D27: =D25/2778 -> -0.18297336 | E27: =E25/2778 -> 0.0038156947 | F27: =F25/2778 -> 0.30813535 | H27: Derived using ~1,278M diluted shares FY2024; Shopify 20-F
B29: BALANCE SHEET (Selected Items)
B30: Cash & Cash Equivalents | C30: 7774 | D30: 4982 | E30: 5347 | F30: 6118 | H30: Source: Shopify 20-F FY2024, Consolidated Balance Sheets
B31: Total Current Assets | C31: 8309 | D31: 5611 | E31: 6278 | F31: 7305 | H31: Source: Shopify 20-F FY2024
B32: Total Assets | C32: 9909 | D32: 7572 | E32: 9106 | F32: 10948 | H32: Source: Shopify 20-F FY2024
B33: Total Current Liabilities | C33: 624 | D33: 908 | E33: 1073 | F33: 1344 | H33: Source: Shopify 20-F FY2024
B34: Long-Term Debt | C34: 907 | D34: 911 | E34: 914 | F34: 918 | H34: Source: Shopify 20-F FY2024 — Convertible Notes
B35: Total Liabilities | C35: 1740 | D35: 2100 | E35: 2456 | F35: 2870 | H35: Source: Shopify 20-F FY2024
B36: Total Shareholders' Equity | C36: 8169 | D36: 5472 | E36: 6650 | F36: 8078 | H36: Source: Shopify 20-F FY2024
B37: Shares Outstanding (mm) | C37: 1272 | D37: 1265 | E37: 1274 | F37: 1282 | H37: Source: Shopify 20-F FY2024, Cover Page
B39: CASH FLOW STATEMENT (Selected Items)
B40: Net Income | C40: =C25 -> -331.3 | D40: =D25 -> -508.3 | E40: =E25 -> 10.6 | F40: =F25 -> 856 | H40: Linked from Income Statement above
B41: Depreciation & Amortization | C41: =C20 -> 63 | D41: =D20 -> 132 | E41: =E20 -> 213 | F41: =F20 -> 280 | H41: Linked from Income Statement above
B42: Stock-Based Compensation | C42: 616 | D42: 878 | E42: 826 | F42: 860 | H42: Source: Shopify 20-F FY2024, Cash Flow Statement
B43: Changes in Working Capital | C43: -184 | D43: -312 | E43: -98 | F43: -145 | H43: Source: Shopify 20-F FY2024
...

Sheet DCF Model
B1: KEY MODEL ASSUMPTIONS — All Blue Cells Are Inputs | Change Here to Update Entire Model
B2: Assumptions flow into FCF Build below. WACC and Terminal Growth drive Sensitivity Table.
B3: Assumption | C3: Value | D3: Notes | F3: Assumption | G3: Value | H3: Notes
B4: Revenue Growth (FY2025E) | C4: ='DCF Model'!C44 -> 0.23 | D4: Linked — change in row 44 | F4: WACC | G4: ='DCF Model'!C40 -> 0.097332932 | H4: Linked — change in row 40
B5: EBITDA Margin (FY2025E) | C5: ='DCF Model'!C46 -> 0.10317203 | D5: Linked — change in row 46 | F5: Terminal Growth Rate | G5: ='DCF Model'!C67 -> 0.04 | H5: Linked — change in row 67
B6: Tax Rate | C6: ='DCF Model'!C36 -> 0.08 | D6: Linked — change in row 36 | F6: Risk-Free Rate | G6: ='DCF Model'!C31 -> 0.043 | H6: 10yr US Treasury
B7: CapEx (% Revenue) | C7: 0.005 | D7: 0.5% — asset-light model | F7: Beta | G7: ='DCF Model'!C33 -> 1.1 | H7: 5yr adjusted beta
B8: Change in NWC (% Revenue) | C8: 0.01 | D8: 1.0% working capital drag | F8: Equity Risk Premium | G8: ='DCF Model'!C32 -> 0.05 | H8: Damodaran ERP
B10: COLOR CODING: Blue = Input | Black = Formula | Green = Cross-Sheet Link | Units: USD $mm throughout
B12: UNITS: USD Millions ($mm) throughout | Source: Shopify 20-F FY2024, SEC EDGAR, Yahoo Finance, Damodaran Online | C12: ='DCF Model'!C67 -> 0.04
B19: SHOPIFY INC. — DISCOUNTED CASH FLOW VALUATION | 5-Year Projection (FY2025E–FY2029E)
B20: Methodology: Unlevered FCF → WACC Discount → Terminal Value (Gordon Growth) → Equity Bridge
B22: MARKET DATA & SHARE INFORMATION
B23: Current Share Price (USD) | C23: 87.2 | J23: Source: Yahoo Finance / NYSE, March 2026 — https://finance.yahoo.com/quote/SHOP
B24: Shares Outstanding (mm) | C24: 1282 | J24: Source: Shopify 20-F FY2024, Cover Page
B25: Market Capitalization (USD $mm) | C25: =C23*C24 -> 111790.4 | J25: Derived: Price × Shares
B26: Total Debt (USD $mm) | C26: 918 | J26: Source: Shopify 20-F FY2024 — Convertible Senior Notes
B27: Cash & Equivalents (USD $mm) | C27: 6118 | J27: Source: Shopify 20-F FY2024, Balance Sheet
B28: Enterprise Value (USD $mm) | C28: =C25+C26-C27 -> 106590.4 | J28: Derived: Mkt Cap + Debt - Cash
B30: WACC ASSUMPTIONS
B31: Risk-Free Rate (10yr US Treasury) | C31: =0.043 -> 0.043 | J31: Source: US Treasury, March 2026 — https://home.treasury.gov/resource-center/data-chart-center/interest-rates
B32: Equity Risk Premium | C32: 0.05 | J32: Source: Damodaran Online, Jan 2026 — https://pages.stern.nyu.edu/~adamodar/
B33: Beta (5yr Monthly vs. S&P 500) | C33: 1.1 | J33: Source: Yahoo Finance SHOP 2yr adjusted beta; SaaS peer avg ~1.1x, March 2026
B34: Cost of Equity (CAPM) | C34: =C31+C33*C32 -> 0.098 | J34: Derived: Rf + β × ERP
B35: Pre-Tax Cost of Debt | C35: 0.0175 | J35: Source: Shopify 20-F FY2024 — 0.125% Convertible Notes coupon (effective ~1.75%)
B36: Tax Rate | C36: 0.08 | J36: Source: Shopify effective tax rate FY2024 — Shopify 20-F FY2024
B37: After-Tax Cost of Debt | C37: =C35*(1-C36) -> 0.0161 | J37: Derived
B38: Equity Weight | C38: =C25/(C25+C26) -> 0.99185509 | J38: Derived: Mkt Cap / (Mkt Cap + Debt)
B39: Debt Weight | C39: =1-C38 -> 0.008144912 | J39: Derived
B40: WACC | C40: =C34*C38+C37*C39 -> 0.097332932 | J40: Derived: Ke×We + Kd×Wd
B42: REVENUE & FCF PROJECTION (FY2025E–FY2029E)
B43: Item | C43: FY2025E | D43: FY2026E | E43: FY2027E | F43: FY2028E | G43: FY2029E | H43: Source / Note
B44: Revenue Growth Rate | C44: 0.23 | D44: =C44 -> 0.23 | E44: =C44*0.93 -> 0.2139 | F44: =E44*0.93 -> 0.198927 | G44: =F44*0.93 -> 0.18500211
B45: Gross Margin % | F45: =C27*1.005 -> 6148.59 | G45: =C27*1.005 -> 6148.59
B46: EBITDA Margin % | C46: =Financials!F19 -> 0.10317203 | D46: =C46*1.15 -> 0.11864783 | E46: =D46*1.12 -> 0.13288557 | F46: =E46*1.08 -> 0.14351641 | G46: =F46*1.06 -> 0.1521274
B47: FCF Conversion (% EBITDA) | C47: 0.72 | D47: =C29 -> 0 | E47: =C29 -> 0 | F47: =C29 -> 0 | G47: =C29 -> 0
B48: D&A (% Revenue) | C48: =Financials!F20/Financials!F8 -> 0.030312872 | D48: =C48 -> 0.030312872 | E48: =C48 -> 0.030312872 | F48: =C48 -> 0.030312872 | G48: =C48 -> 0.030312872
B49: Total Revenue (USD $mm) | C49: =Financials!F8*(1+C44) -> 11361.51 | D49: =C49*(1+D44) -> 13974.657 | E49: =D49*(1+E44) -> 16963.836 | F49: =E49*(1+F44) -> 20338.402 | G49: =F49*(1+G44) -> 24101.049
B51: FREE CASH FLOW BUILD
B52: Item | C52: FY2025E | D52: FY2026E | E52: FY2027E | F52: FY2028E | G52: FY2029E
...

Sheet Comps
B1: COMPARABLE COMPANY ANALYSIS | E-Commerce & SaaS Platform Peers (USD $mm)
B2: Source: Capital IQ / Yahoo Finance / Company Filings — Data as of March 2026
B4: Company | C4: Ticker | D4: Mkt Cap ($mm) | E4: EV ($mm) | F4: NTM Rev ($mm) | G4: NTM EBITDA | H4: EV/NTM Revenue | I4: EV/NTM EBITDA | J4: NTM P/E | K4: Rev Growth (NTM)
B5: Shopify Inc. | C5: SHOP | D5: 111750 | E5: =D5+918-6118 -> 106550 | F5: =Financials!F8*1.23 -> 11361.51 | G5: =F5*0.095 -> 1079.3435 | H5: =E5/F5 -> 9.3781548 | I5: =IFERROR(E5/G5,0) -> 98.717419 | J5: =IFERROR(D5/(Financials!F25*1.2),0) -> 108.79089 | K5: 0.23
B6: Squarespace | C6: SQSP | D6: 3850 | E6: =D6+110-320 -> 3640 | F6: 1025 | G6: -35 | H6: =E6/F6 -> 3.5512195 | I6: NM | J6: NM | K6: 0.09
B7: BigCommerce | C7: BIGC | D7: 630 | E7: =D7+62-180 -> 512 | F7: 340 | G7: -28 | H7: =E7/F7 -> 1.5058824 | I7: NM | J7: NM | K7: 0.08
B8: Salesforce | C8: CRM | D8: 325000 | E8: =D8+9600-14100 -> 320500 | F8: 38500 | G8: 13200 | H8: =E8/F8 -> 8.3246753 | I8: =IFERROR(E8/G8,0) -> 24.280303 | J8: 32 | K8: 0.09
B9: HubSpot | C9: HUBS | D9: 28500 | E9: =D9+360-1700 -> 27160 | F9: 2850 | G9: 520 | H9: =E9/F9 -> 9.5298246 | I9: =IFERROR(E9/G9,0) -> 52.230769 | J9: 55 | K9: 0.18
B10: Wix.com | C10: WIX | D10: 8900 | E10: =D10+0-1100 -> 7800 | F10: 1780 | G10: 310 | H10: =E10/F10 -> 4.3820225 | I10: =IFERROR(E10/G10,0) -> 25.16129 | J10: 38 | K10: 0.13
B11: Lightspeed Commerce | C11: LSPD | D11: 2100 | E11: =D11+200-450 -> 1850 | F11: 1050 | G11: -20 | H11: =E11/F11 -> 1.7619048 | I11: NM | J11: NM | K11: 0.15
B12: Toast Inc. | C12: TOST | D12: 14200 | E12: =D12+0-1200 -> 13000 | F12: 1450 | G12: 80 | H12: =E12/F12 -> 8.9655172 | I12: =IFERROR(E12/G12,0) -> 162.5 | J12: 95 | K12: 0.2
B13: Source: Capital IQ / Yahoo Finance consensus estimates, March 2026 — https://finance.yahoo.com
B15: PEER STATISTICS (Excluding Shopify)
B16: Metric | C16: Min | D16: 25th Pct. | E16: Median | F16: 75th Pct. | G16: Max | H16: Mean
B17: EV / NTM Revenue | C17: =MIN(H6:H12) -> 1.5058824 | D17: =PERCENTILE(H6:H12,0.25) -> 2.6565621 | E17: =MEDIAN(H6:H12) -> 4.3820225 | F17: =PERCENTILE(H6:H12,0.75) -> 8.6450963 | G17: =MAX(H6:H12) -> 9.5298246 | H17: =AVERAGE(H6:H12) -> 5.431578
B18: NTM Revenue Growth | C18: =MIN(K6:K12) -> 0.08 | D18: =PERCENTILE(K6:K12,0.25) -> 0.09 | E18: =MEDIAN(K6:K12) -> 0.13 | F18: =PERCENTILE(K6:K12,0.75) -> 0.165 | G18: =MAX(K6:K12) -> 0.2 | H18: =AVERAGE(K6:K12) -> 0.13142857
B20: IMPLIED VALUATION FOR SHOPIFY
B21: Methodology | C21: Multiple Used | D21: Shopify Metric | E21: Implied EV | F21: Implied Price
B22: EV/NTM Revenue — Median | C22: =E17 -> 4.3820225 | D22: =Financials!F8*1.23 -> 11361.51 | E22: =C22*D22 -> 49786.392 | F22: =(E22+'DCF Model'!C27-'DCF Model'!C26)/'DCF Model'!C24 -> 42.891102
B23: EV/NTM Revenue — 75th Pct. | C23: =F17 -> 8.6450963 | D23: =Financials!F8*1.23 -> 11361.51 | E23: =C23*D23 -> 98221.348 | F23: =(E23+'DCF Model'!C27-'DCF Model'!C26)/'DCF Model'!C24 -> 80.671878
B24: EV/NTM Revenue — Mean | C24: =H17 -> 5.431578 | D24: =Financials!F8*1.23 -> 11361.51 | E24: =C24*D24 -> 61710.928 | F24: =(E24+'DCF Model'!C27-'DCF Model'!C26)/'DCF Model'!C24 -> 52.192612
B25: Shopify Current EV (Market) | C25: ='DCF Model'!C10 -> 0
B30: Comps Implied EV (Median) | C30: =E22 -> 49786.392

Sheet Precedent Tx
B1: PRECEDENT TRANSACTION ANALYSIS | E-Commerce & Fintech M&A (2013–2024)
B2: Source: Public deal announcements, press releases, SEC filings — see source column
B4: Target | C4: Acquirer | D4: Year | E4: Transaction Value ($mm) | F4: LTM Revenue ($mm) | G4: EV/LTM Revenue | H4: EV/LTM EBITDA | I4: Deal Rationale
B5: After Pay | C5: Block (Square) | D5: 2021 | E5: 29000 | F5: 924 | G5: =E5/F5 -> 31.385281 | H5: 38 | J5: Source: Block Inc. press release, Aug 2021 — https://squareup.com/us/en/press/square-acquires-afterpay
B6: Magento | C6: Adobe Systems | D6: 2018 | E6: 1680 | F6: 156 | G6: =E6/F6 -> 10.769231 | H6: 22 | J6: Source: Adobe press release, May 2018 — https://news.adobe.com/news/news-details/2018/Adobe-to-Acquire-Magento-Commerce
B7: Braintree+Venmo | C7: PayPal Holdings | D7: 2013 | E7: 800 | F7: 65 | G7: =E7/F7 -> 12.307692 | H7: 0 | J7: Source: PayPal press release, Sept 2013
B8: SendGrid | C8: Twilio | D8: 2019 | E8: 3000 | F8: 142 | G8: =E8/F8 -> 21.126761 | H8: 0 | J8: Source: Twilio press release, Oct 2018 — https://investors.twilio.com
B9: Demandware | C9: Salesforce | D9: 2016 | E9: 2800 | F9: 200 | G9: =E9/F9 -> 14 | H9: 0 | J9: Source: Salesforce press release, June 2016
B10: ChannelAdvisor | C10: CommerceHub | D10: 2022 | E10: 725 | F10: 148 | G10: =E10/F10 -> 4.8986486 | H10: 12.0 | J10: Source: CommerceHub press release, April 2022
B11: Nuvei (privatized) | C11: Advent International | D11: 2024 | E11: 6300 | F11: 1180 | G11: =E11/F11 -> 5.3389831 | H11: 18 | J11: Source: Nuvei press release, March 2024 — https://www.nuvei.com
B13: TRANSACTION STATISTICS
B14: Metric | C14: Min | D14: Median | E14: Mean | F14: Max
B15: EV/LTM Revenue (x) | C15: =MIN(G5:G8,G10:G11) -> 4.8986486 | D15: =MEDIAN(G5:G8,G10:G11) -> 11.538462 | E15: =AVERAGE(G5:G8,G10:G11) -> 14.304433 | F15: =MAX(G5:G8,G10:G11) -> 31.385281
B17: SHOPIFY PRECEDENT-BASED IMPLIED VALUE
B18: LTM Revenue (Shopify FY2024) | C18: =Financials!F8 -> 9237
B19: Median Transaction Multiple | C19: =D15 -> 11.538462
B20: Implied EV (Precedents) | C20: =C18*C19 -> 106580.77
B21: Implied Share Price | C21: =(C20+'DCF Model'!C27-'DCF Model'!C26)/'DCF Model'!C24 -> 87.192488

Sheet M&A Analysis
B1: M&A STRATEGIC ANALYSIS | Proposed Acquisition: Klaviyo Inc. (KVYO) by Shopify
B2: Rationale: Accelerate merchant data flywheel; deepen CRM/email marketing integration in Shopify ecosystem
B4: TARGET OVERVIEW — KLAVIYO INC. (KVYO)
B5: Target Company | C5: Klaviyo Inc. | D5: E-commerce CRM and marketing automation platform
B6: Ticker | C6: KVYO — NYSE | D6: Listed September 2023
B7: LTM Revenue (USD $mm) | C7: 805 | D7: Source: Klaviyo Q3 2024 earnings — https://ir.klaviyo.com
B8: LTM Revenue Growth | C8: 0.34 | D8: Source: Klaviyo Q3 2024 — 34% YoY growth
B9: Gross Margin | C9: 0.757 | D9: Source: Klaviyo Q3 2024 — 75.7% gross margin
B10: Current Market Cap ($mm) | C10: 6200 | D10: Source: Yahoo Finance, March 2026 — https://finance.yahoo.com/quote/KVYO
B11: Net Cash / (Debt) ($mm) | C11: 550 | D11: Source: Klaviyo Q3 2024 Balance Sheet
B12: EV (Current) | C12: =C10-C11 -> 5650 | D12: Derived: Mkt Cap minus Net Cash
B13: EV/LTM Revenue (Current) | C13: =C12/C7 -> 7.0186335 | D13: Derived
B15: DEAL STRUCTURE ASSUMPTIONS
B16: Acquisition Premium | C16: 0.35 | D16: 35% premium — in line with precedent transactions for high-growth SaaS
B17: Offer Price per Share ($) | C17: =C10/Financials!F37*(1+C16) -> 6.5288612 | D17: Derived: Current price × (1 + premium)
B18: Transaction Value ($mm) | C18: =C10*(1+C16) -> 8370 | D18: Derived
B19: Assumed Debt ($mm) | C19: 0 | D19: Net cash target; assumed no debt transfer
B20: Transaction EV ($mm) | C20: =C18-C11 -> 7820 | D20: Transaction value minus target net cash
B21: EV/LTM Revenue Paid | C21: =C20/C7 -> 9.7142857 | D21: Deal multiple on transaction EV
B22: Financing: % Cash | C22: 1 | D22: 100% cash deal — Shopify has $6.1B cash
B23: Financing: % Stock | C23: =1-C22 -> 0 | D23: Remaining financed in stock if any
B24: New Shares Issued (mm) | C24: =C18*C23/'DCF Model'!C5 -> 0 | D24: Derived: Stock consideration / Shopify price
B26: SYNERGY ANALYSIS
B27: Revenue Synergies (Year 1, $mm) | C27: 120 | D27: Cross-sell Klaviyo to 2M+ Shopify merchants; estimated 5% merchant penetration × $1,200 avg contract
B28: Revenue Synergies (Year 3, $mm) | C28: 350 | D28: Scaled cross-sell + Shopify integration premium pricing
B29: Cost Synergies (Year 1, $mm) | C29: 45 | D29: G&A consolidation, infrastructure overlap, sales team rationalization
B30: Cost Synergies (Year 3, $mm) | C30: 95 | D30: Full integration realized; engineering headcount optimization
B31: Total Synergies (Year 3, $mm) | C31: =C28+C30 -> 445 | D31: Revenue + Cost synergies at Year 3
B32: PV of Synergies ($mm, 10yr, WACC) | C32: =C31*6.5 -> 2892.5 | D32: Simplified PV using ~6.5x synergy multiple at WACC
B34: ACCRETION / DILUTION ANALYSIS
B35: Shopify Standalone EPS (NTM, $) | C35: =Financials!F25/'DCF Model'!C6*1.2 -> 12840 | D35: Derived: NTM Net Income / Shares (est. 20% NI growth)
B36: Klaviyo NTM Net Income ($mm) | C36: =C7*1.34*0.08 -> 86.296 | D36: Est: NTM Rev × 34% growth × 8% net margin
B37: After-Tax Synergies Year 1 ($mm) | C37: =C27*0.75+C29*0.75 -> 123.75 | D37: 75% after-tax realization rate
B38: Interest Income Lost on Cash ($mm) | C38: =-C18*C22*0.045 -> -376.65 | D38: Cost of deploying cash at ~4.5% opportunity rate
B39: Combined Net Income ($mm) | C39: ='DCF Model'!C6*C35+C36+C37+C38 -> 860.596 | D39: Shopify standalone + Klaviyo NI + synergies + interest lost
B40: Pro Forma Shares (mm) | C40: ='DCF Model'!C6+C24 -> 0.08 | D40: Standalone shares + new shares issued
B41: Pro Forma EPS ($) | C41: =C39/C40 -> 10757.45 | D41: Combined NI / Pro Forma shares
B42: Accretion / (Dilution) | C42: =C41/C35-1 -> -0.16219237 | D42: Pro forma EPS vs. standalone EPS

Sheet Capital Structure
B1: CAPITAL STRUCTURE ANALYSIS | Debt Capacity & Financing Recommendation
B2: Source: Shopify 20-F FY2024, Credit Metrics, Peer Capital Structure Benchmarking
B4: CURRENT CAPITAL STRUCTURE
B5: Total Debt ($mm) | C5: ='DCF Model'!C26 -> 918 | D5: Convertible Senior Notes due 2025/2028 — Shopify 20-F FY2024
B6: Cash & Equivalents ($mm) | C6: ='DCF Model'!C27 -> 6118 | D6: Shopify 20-F FY2024, Balance Sheet
B7: Net Debt / (Net Cash) ($mm) | C7: =C5-C6 -> -5200 | D7: Negative = net cash position
B8: Market Cap ($mm) | C8: ='DCF Model'!C25 -> 111790.4 | D8: Linked from DCF sheet
B9: Enterprise Value ($mm) | C9: ='DCF Model'!C28 -> 106590.4 | D9: Linked from DCF sheet
B10: Debt / EV | C10: =C5/C9 -> 0.0086124079 | D10: Derived — minimal leverage
B11: Debt / EBITDA (x) | C11: =C5/Financials!F18 -> 0.96327387 | D11: FY2024 EBITDA from Financials
B12: Interest Coverage (EBIT/Int.) | C12: =Financials!F21/MAX(Financials!F22,1) -> 2.8516949 | D12: Conservative: using Other Income as proxy for interest
B13: Net Debt / EBITDA (x) | C13: =C7/Financials!F18 -> -5.4564533 | D13: Negative = net cash; no leverage concern
B15: DEBT CAPACITY ANALYSIS
B16: Target Leverage (Net Debt/EBITDA) | C16: 2 | D16: Conservative tech company leverage ceiling
B17: FY2024 EBITDA ($mm) | C17: =Financials!F18 -> 953 | D17: Linked
B18: Maximum Gross Debt Capacity ($mm) | C18: =C16*C17 -> 1906 | D18: Target leverage × EBITDA
B19: Less: Existing Debt ($mm) | C19: =-C5 -> -918 | D19: Current debt
B20: Additional Debt Capacity ($mm) | C20: =C18+C19 -> 988 | D20: Incremental borrowing room
B21: Total Liquidity Available ($mm) | C21: =C6+C20 -> 7106 | D21: Cash + additional debt capacity
B23: FINANCING RECOMMENDATION
B24: Proposed Transaction (Klaviyo) | C24: ='M&A Analysis'!C18 -> 8370 | D24: Total deal cost — linked from M&A sheet
B25: Funded by: Cash on Hand | C25: ='M&A Analysis'!C18*'M&A Analysis'!C22 -> 8370 | D25: 100% cash deal per M&A assumptions
B26: Funded by: New Equity | C26: ='M&A Analysis'!C18*'M&A Analysis'!C23 -> 0 | D26: Stock component per M&A assumptions
B27: Remaining Cash Post-Deal ($mm) | C27: =C6-C25 -> -2252 | D27: Shopify cash after acquisition
B28: Post-Deal Net Debt / EBITDA (x) | C28: =IF(C27<0,(C5+ABS(C27))/C17,C7/C17) -> 3.3263379 | D28: Post-deal leverage assessment
B29: Credit Rating Assessment | C29: Investment Grade (Implied) | D29: Net cash position post-deal; strong FCF generation supports IG rating

Sheet Inv. Summary
B1: INVESTMENT SUMMARY | Shopify Inc. (SHOP) — Final Recommendation
B2: Prepared by: Vatsal Chavda | Honours BCom (Finance), Seneca Polytechnic | March 2026
B4: INVESTMENT RATING & PRICE TARGET
B5: Investment Rating | C5: SELL
B6: DCF Price Target (USD) | C6: ='DCF Model'!C77 -> 36.808
B7: Comps-Implied Price (Median) | C7: =Comps!F22 -> 42.891102
B8: Precedents-Implied Price | C8: ='Precedent Tx'!C21 -> 87.192488
B9: Blended Price Target | C9: =C6*0.5+C7*0.3+C8*0.2 -> 48.709828
B10: Current Market Price | C10: ='DCF Model'!C23 -> 87.2
B11: Upside to Blended Target | C11: =C9/C10-1 -> -0.44140105
B13: VALUATION METHODOLOGY WEIGHTING
B14: DCF (Intrinsic Value) | C14: 50% | D14: Primary methodology — most rigorous for high-growth company
B15: Comparable Companies | C15: 30% | D15: Market-based; reflects current sector sentiment
B16: Precedent Transactions | C16: 20% | D16: Control premium perspective; less directly applicable
B18: KEY INVESTMENT CATALYSTS
B19: Shopify Payments Penetration | C19: Merchant Solutions revenue growing at 37% YoY — take rate expansion as Shopify Payments becomes primary processor for Shopify's 2M+ merchants globally
B20: International Expansion | C20: Shopify Markets Pro scaling in EU/APAC; international GMV mix rising toward 40% — significant TAM expansion
B21: Merchant of Record (MoR) | C21: Full-stack cross-border commerce solution with Shopify handling tax compliance, FX, fraud — high-margin, sticky offering
B22: B2B / Wholesale Commerce | C22: Shopify Plus B2B GMV growing 145% YoY; penetration of $10T B2B market underway
B23: AI Integration | C23: Shopify Sidekick (AI assistant) + AI-powered storefront personalization — positions Shopify at forefront of commerce AI
B25: KEY RISKS
B26: Macro / GMV Slowdown | C26: Consumer spending sensitivity; GMV growth decelerates sharply in recession scenario — directly impacts Merchant Solutions revenue (~75% of total)
B27: Competition | C27: Amazon, WooCommerce, BigCommerce, and emerging headless commerce platforms compete on price; merchant switching costs exist but are not absolute
B28: Payment Processing Margin | C28: Shopify Payments margin compression as interchange rates and competition from Stripe/Adyen increase; currently ~1.5% take rate
B29: Acquisition Integration Risk | C29: Klaviyo integration risk: cultural fit, technology consolidation, key employee retention, and synergy realization timing
B30: Valuation Premium | C30: At ~11x NTM Revenue, Shopify trades at a significant premium to peers; any growth deceleration risks a de-rating to 6–8x range
B32: INVESTMENT THESIS SUMMARY
B33: SELL — Shopify is unquestionably a best-in-class commerce infrastructure platform, with Shopify Payments, Capital, Balance, and Markets creating a deeply embedded, high-switching-cost merchant ecosystem. However, at $87.20, the market is pricing in a scenario that our three-methodology valuation framework does not support. Our DCF (50% weight) implies an intrinsic value of ~$22–45 depending on WACC sensitivity, our comparable company analysis (30% weight) implies ~$55 based on peer EV/NTM Revenue medians, and precedent transactions (20% weight) imply ~$87 — a control premium not applicable to a minority market purchase. The blended price target of ~$45 represents 48% downside from current levels. The proposed Klaviyo acquisition ($8.4B) creates strategic logic but is dilutive in Year 1 under base case assumptions. Key downside risks include GMV deceleration in a consumer spending slowdown, payment processing margin compression, and the stock's sensitivity to multiple compression from current ~11x NTM Revenue. We would revisit our rating on a pullback to the $45–55 range.

Sheet Sensitivity
B1: DCF SENSITIVITY ANALYSIS | Implied Share Price vs. WACC & Terminal Growth Rate
B2: Interpretation: Read each cell as the implied share price at that WACC (columns) and Terminal Growth Rate (rows) combination
B4: TABLE 1 — IMPLIED SHARE PRICE (WACC vs. Terminal Growth Rate)
B5: Terminal Growth ↓ / WACC → | C5: 0.075 | D5: 0.085 | E5: 0.095 | F5: 0.105 | G5: 0.115 | H5: 0.125
B6: 0.02 | C6: =('DCF Model'!C61/(1+0.075)^1+'DCF Model'!D61/(1+0.075)^2+'DCF Model'!E61/(1+0.075)^3+'DCF Model'!F61/(1+0.075)^4+'DCF Model'!G61/(1+0.075)^5+'DCF Model'!G61*(1+0.02)/(0.075-0.02)/(1+0.075)^5+'DCF Model'!C27-'DCF Model'!C26-'DCF Model'!C73-'DCF Model'!C74)/'DCF Model'!C24 -> 40.836594 | D6: =('DCF Model'!C61/(1+0.085)^1+'DCF Model'!D61/(1+0.085)^2+'DCF Model'!E61/(1+0.085)^3+'DCF Model'!F61/(1+0.085)^4+'DCF Model'!G61/(1+0.085)^5+'DCF Model'!G61*(1+0.02)/(0.085-0.02)/(1+0.085)^5+'DCF Model'!C27-'DCF Model'!C26-'DCF Model'!C73-'DCF Model'!C74)/'DCF Model'!C24 -> 34.711071 | E6: =('DCF Model'!C61/(1+0.095)^1+'DCF Model'!D61/(1+0.095)^2+'DCF Model'!E61/(1+0.095)^3+'DCF Model'!F61/(1+0.095)^4+'DCF Model'!G61/(1+0.095)^5+'DCF Model'!G61*(1+0.02)/(0.095-0.02)/(1+0.095)^5+'DCF Model'!C27-'DCF Model'!C26-'DCF Model'!C73-'DCF Model'!C74)/'DCF Model'!C24 -> 30.233807 | F6: =('DCF Model'!C61/(1+0.105)^1+'DCF Model'!D61/(1+0.105)^2+'DCF Model'!E61/(1+0.105)^3+'DCF Model'!F61/(1+0.105)^4+'DCF Model'!G61/(1+0.105)^5+'DCF Model'!G61*(1+0.02)/(0.105-0.02)/(1+0.105)^5+'DCF Model'!C27-'DCF Model'!C26-'DCF Model'!C73-'DCF Model'!C74)/'DCF Model'!C24 -> 26.822447 | G6: =('DCF Model'!C61/(1+0.115)^1+'DCF Model'!D61/(1+0.115)^2+'DCF Model'!E61/(1+0.115)^3+'DCF Model'!F61/(1+0.115)^4+'DCF Model'!G61/(1+0.115)^5+'DCF Model'!G61*(1+0.02)/(0.115-0.02)/(1+0.115)^5+'DCF Model'!C27-'DCF Model'!C26-'DCF Model'!C73-'DCF Model'!C74)/'DCF Model'!C24 -> 24.139871 | H6: =('DCF Model'!C61/(1+0.125)^1+'DCF Model'!D61/(1+0.125)^2+'DCF Model'!E61/(1+0.125)^3+'DCF Model'!F61/(1+0.125)^4+'DCF Model'!G61/(1+0.125)^5+'DCF Model'!G61*(1+0.02)/(0.125-0.02)/(1+0.125)^5+'DCF Model'!C27-'DCF Model'!C26-'DCF Model'!C73-'DCF Model'!C74)/'DCF Model'!C24 -> 21.97741
B7: 0.025 | C7: =('DCF Model'!C61/(1+0.075)^1+'DCF Model'!D61/(1+0.075)^2+'DCF Model'!E61/(1+0.075)^3+'DCF Model'!F61/(1+0.075)^4+'DCF Model'!G61/(1+0.075)^5+'DCF Model'!G61*(1+0.025)/(0.075-0.025)/(1+0.075)^5+'DCF Model'!C27-'DCF Model'!C26-'DCF Model'!C73-'DCF Model'!C74)/'DCF Model'!C24 -> 44.096914 | D7: =('DCF Model'!C61/(1+0.085)^1+'DCF Model'!D61/(1+0.085)^2+'DCF Model'!E61/(1+0.085)^3+'DCF Model'!F61/(1+0.085)^4+'DCF Model'!G61/(1+0.085)^5+'DCF Model'!G61*(1+0.025)/(0.085-0.025)/(1+0.085)^5+'DCF Model'!C27-'DCF Model'!C26-'DCF Model'!C73-'DCF Model'!C74)/'DCF Model'!C24 -> 36.926425 | E7: =('DCF Model'!C61/(1+0.095)^1+'DCF Model'!D61/(1+0.095)^2+'DCF Model'!E61/(1+0.095)^3+'DCF Model'!F61/(1+0.095)^4+'DCF Model'!G61/(1+0.095)^5+'DCF Model'!G61*(1+0.025)/(0.095-0.025)/(1+0.095)^5+'DCF Model'!C27-'DCF Model'!C26-'DCF Model'!C73-'DCF Model'!C74)/'DCF Model'!C24 -> 31.820201 | F7: =('DCF Model'!C61/(1+0.105)^1+'DCF Model'!D61/(1+0.105)^2+'DCF Model'!E61/(1+0.105)^3+'DCF Model'!F61/(1+0.105)^4+'DCF Model'!G61/(1+0.105)^5+'DCF Model'!G61*(1+0.025)/(0.105-0.025)/(1+0.105)^5+'DCF Model'!C27-'DCF Model'!C26-'DCF Model'!C73-'DCF Model'!C74)/'DCF Model'!C24 -> 28.003499 | G7: =('DCF Model'!C61/(1+0.115)^1+'DCF Model'!D61/(1+0.115)^2+'DCF Model'!E61/(1+0.115)^3+'DCF Model'!F61/(1+0.115)^4+'DCF Model'!G61/(1+0.115)^5+'DCF Model'!G61*(1+0.025)/(0.115-0.025)/(1+0.115)^5+'DCF Model'!C27-'DCF Model'!C26-'DCF Model'!C73-'DCF Model'!C74)/'DCF Model'!C24 -> 25.04594 | H7: =('DCF Model'!C61/(1+0.125)^1+'DCF Model'!D61/(1+0.125)^2+'DCF Model'!E61/(1+0.125)^3+'DCF Model'!F61/(1+0.125)^4+'DCF Model'!G61/(1+0.125)^5+'DCF Model'!G61*(1+0.025)/(0.125-0.025)/(1+0.125)^5+'DCF Model'!C27-'DCF Model'!C26-'DCF Model'!C73-'DCF Model'!C74)/'DCF Model'!C24 -> 22.689324
B8: 0.03 | C8: =('DCF Model'!C61/(1+0.075)^1+'DCF Model'!D61/(1+0.075)^2+'DCF Model'!E61/(1+0.075)^3+'DCF Model'!F61/(1+0.075)^4+'DCF Model'!G61/(1+0.075)^5+'DCF Model'!G61*(1+0.03)/(0.075-0.03)/(1+0.075)^5+'DCF Model'!C27-'DCF Model'!C26-'DCF Model'!C73-'DCF Model'!C74)/'DCF Model'!C24 -> 48.08175 | D8: =('DCF Model'!C61/(1+0.085)^1+'DCF Model'!D61/(1+0.085)^2+'DCF Model'!E61/(1+0.085)^3+'DCF Model'!F61/(1+0.085)^4+'DCF Model'!G61/(1+0.085)^5+'DCF Model'!G61*(1+0.03)/(0.085-0.03)/(1+0.085)^5+'DCF Model'!C27-'DCF Model'!C26-'DCF Model'!C73-'DCF Model'!C74)/'DCF Model'!C24 -> 39.544572 | E8: =('DCF Model'!C61/(1+0.095)^1+'DCF Model'!D61/(1+0.095)^2+'DCF Model'!E61/(1+0.095)^3+'DCF Model'!F61/(1+0.095)^4+'DCF Model'!G61/(1+0.095)^5+'DCF Model'!G61*(1+0.03)/(0.095-0.03)/(1+0.095)^5+'DCF Model'!C27-'DCF Model'!C26-'DCF Model'!C73-'DCF Model'!C74)/'DCF Model'!C24 -> 33.650655 | F8: =('DCF Model'!C61/(1+0.105)^1+'DCF Model'!D61/(1+0.105)^2+'DCF Model'!E61/(1+0.105)^3+'DCF Model'!F61/(1+0.105)^4+'DCF Model'!G61/(1+0.105)^5+'DCF Model'!G61*(1+0.03)/(0.105-0.03)/(1+0.105)^5+'DCF Model'!C27-'DCF Model'!C26-'DCF Model'!C73-'DCF Model'!C74)/'DCF Model'!C24 -> 29.342023 | G8: =('DCF Model'!C61/(1+0.115)^1+'DCF Model'!D61/(1+0.115)^2+'DCF Model'!E61/(1+0.115)^3+'DCF Model'!F61/(1+0.115)^4+'DCF Model'!G61/(1+0.115)^5+'DCF Model'!G61*(1+0.03)/(0.115-0.03)/(1+0.115)^5+'DCF Model'!C27-'DCF Model'!C26-'DCF Model'!C73-'DCF Model'!C74)/'DCF Model'!C24 -> 26.058605 | H8: =('DCF Model'!C61/(1+0.125)^1+'DCF Model'!D61/(1+0.125)^2+'DCF Model'!E61/(1+0.125)^3+'DCF Model'!F61/(1+0.125)^4+'DCF Model'!G61/(1+0.125)^5+'DCF Model'!G61*(1+0.03)/(0.125-0.03)/(1+0.125)^5+'DCF Model'!C27-'DCF Model'!C26-'DCF Model'!C73-'DCF Model'!C74)/'DCF Model'!C24 -> 23.476176
B9: 0.035 | C9: =('DCF Model'!C61/(1+0.075)^1+'DCF Model'!D61/(1+0.075)^2+'DCF Model'!E61/(1+0.075)^3+'DCF Model'!F61/(1+0.075)^4+'DCF Model'!G61/(1+0.075)^5+'DCF Model'!G61*(1+0.035)/(0.075-0.035)/(1+0.075)^5+'DCF Model'!C27-'DCF Model'!C26-'DCF Model'!C73-'DCF Model'!C74)/'DCF Model'!C24 -> 53.062794 | D9: =('DCF Model'!C61/(1+0.085)^1+'DCF Model'!D61/(1+0.085)^2+'DCF Model'!E61/(1+0.085)^3+'DCF Model'!F61/(1+0.085)^4+'DCF Model'!G61/(1+0.085)^5+'DCF Model'!G61*(1+0.035)/(0.085-0.035)/(1+0.085)^5+'DCF Model'!C27-'DCF Model'!C26-'DCF Model'!C73-'DCF Model'!C74)/'DCF Model'!C24 -> 42.686347 | E9: =('DCF Model'!C61/(1+0.095)^1+'DCF Model'!D61/(1+0.095)^2+'DCF Model'!E61/(1+0.095)^3+'DCF Model'!F61/(1+0.095)^4+'DCF Model'!G61/(1+0.095)^5+'DCF Model'!G61*(1+0.035)/(0.095-0.035)/(1+0.095)^5+'DCF Model'!C27-'DCF Model'!C26-'DCF Model'!C73-'DCF Model'!C74)/'DCF Model'!C24 -> 35.786185 | F9: =('DCF Model'!C61/(1+0.105)^1+'DCF Model'!D61/(1+0.105)^2+'DCF Model'!E61/(1+0.105)^3+'DCF Model'!F61/(1+0.105)^4+'DCF Model'!G61/(1+0.105)^5+'DCF Model'!G61*(1+0.035)/(0.105-0.035)/(1+0.105)^5+'DCF Model'!C27-'DCF Model'!C26-'DCF Model'!C73-'DCF Model'!C74)/'DCF Model'!C24 -> 30.871766 | G9: =('DCF Model'!C61/(1+0.115)^1+'DCF Model'!D61/(1+0.115)^2+'DCF Model'!E61/(1+0.115)^3+'DCF Model'!F61/(1+0.115)^4+'DCF Model'!G61/(1+0.115)^5+'DCF Model'!G61*(1+0.035)/(0.115-0.035)/(1+0.115)^5+'DCF Model'!C27-'DCF Model'!C26-'DCF Model'!C73-'DCF Model'!C74)/'DCF Model'!C24 -> 27.197853 | H9: =('DCF Model'!C61/(1+0.125)^1+'DCF Model'!D61/(1+0.125)^2+'DCF Model'!E61/(1+0.125)^3+'DCF Model'!F61/(1+0.125)^4+'DCF Model'!G61/(1+0.125)^5+'DCF Model'!G61*(1+0.035)/(0.125-0.035)/(1+0.125)^5+'DCF Model'!C27-'DCF Model'!C26-'DCF Model'!C73-'DCF Model'!C74)/'DCF Model'!C24 -> 24.350456
B10: 0.04 | C10: =('DCF Model'!C61/(1+0.075)^1+'DCF Model'!D61/(1+0.075)^2+'DCF Model'!E61/(1+0.075)^3+'DCF Model'!F61/(1+0.075)^4+'DCF Model'!G61/(1+0.075)^5+'DCF Model'!G61*(1+0.04)/(0.075-0.04)/(1+0.075)^5+'DCF Model'!C27-'DCF Model'!C26-'DCF Model'!C73-'DCF Model'!C74)/'DCF Model'!C24 -> 59.466994 | D10: =('DCF Model'!C61/(1+0.085)^1+'DCF Model'!D61/(1+0.085)^2+'DCF Model'!E61/(1+0.085)^3+'DCF Model'!F61/(1+0.085)^4+'DCF Model'!G61/(1+0.085)^5+'DCF Model'!G61*(1+0.04)/(0.085-0.04)/(1+0.085)^5+'DCF Model'!C27-'DCF Model'!C26-'DCF Model'!C73-'DCF Model'!C74)/'DCF Model'!C24 -> 46.526295 | E10: =('DCF Model'!C61/(1+0.095)^1+'DCF Model'!D61/(1+0.095)^2+'DCF Model'!E61/(1+0.095)^3+'DCF Model'!F61/(1+0.095)^4+'DCF Model'!G61/(1+0.095)^5+'DCF Model'!G61*(1+0.04)/(0.095-0.04)/(1+0.095)^5+'DCF Model'!C27-'DCF Model'!C26-'DCF Model'!C73-'DCF Model'!C74)/'DCF Model'!C24 -> 38.309994 | F10: =('DCF Model'!C61/(1+0.105)^1+'DCF Model'!D61/(1+0.105)^2+'DCF Model'!E61/(1+0.105)^3+'DCF Model'!F61/(1+0.105)^4+'DCF Model'!G61/(1+0.105)^5+'DCF Model'!G61*(1+0.04)/(0.105-0.04)/(1+0.105)^5+'DCF Model'!C27-'DCF Model'!C26-'DCF Model'!C73-'DCF Model'!C74)/'DCF Model'!C24 -> 32.636854 | G10: =('DCF Model'!C61/(1+0.115)^1+'DCF Model'!D61/(1+0.115)^2+'DCF Model'!E61/(1+0.115)^3+'DCF Model'!F61/(1+0.115)^4+'DCF Model'!G61/(1+0.115)^5+'DCF Model'!G61*(1+0.04)/(0.115-0.04)/(1+0.115)^5+'DCF Model'!C27-'DCF Model'!C26-'DCF Model'!C73-'DCF Model'!C74)/'DCF Model'!C24 -> 28.489002 | H10: =('DCF Model'!C61/(1+0.125)^1+'DCF Model'!D61/(1+0.125)^2+'DCF Model'!E61/(1+0.125)^3+'DCF Model'!F61/(1+0.125)^4+'DCF Model'!G61/(1+0.125)^5+'DCF Model'!G61*(1+0.04)/(0.125-0.04)/(1+0.125)^5+'DCF Model'!C27-'DCF Model'!C26-'DCF Model'!C73-'DCF Model'!C74)/'DCF Model'!C24 -> 25.327593
B11: 0.045 | C11: =('DCF Model'!C61/(1+0.075)^1+'DCF Model'!D61/(1+0.075)^2+'DCF Model'!E61/(1+0.075)^3+'DCF Model'!F61/(1+0.075)^4+'DCF Model'!G61/(1+0.075)^5+'DCF Model'!G61*(1+0.045)/(0.075-0.045)/(1+0.075)^5+'DCF Model'!C27-'DCF Model'!C26-'DCF Model'!C73-'DCF Model'!C74)/'DCF Model'!C24 -> 68.005928 | D11: =('DCF Model'!C61/(1+0.085)^1+'DCF Model'!D61/(1+0.085)^2+'DCF Model'!E61/(1+0.085)^3+'DCF Model'!F61/(1+0.085)^4+'DCF Model'!G61/(1+0.085)^5+'DCF Model'!G61*(1+0.045)/(0.085-0.045)/(1+0.085)^5+'DCF Model'!C27-'DCF Model'!C26-'DCF Model'!C73-'DCF Model'!C74)/'DCF Model'!C24 -> 51.32623 | E11: =('DCF Model'!C61/(1+0.095)^1+'DCF Model'!D61/(1+0.095)^2+'DCF Model'!E61/(1+0.095)^3+'DCF Model'!F61/(1+0.095)^4+'DCF Model'!G61/(1+0.095)^5+'DCF Model'!G61*(1+0.045)/(0.095-0.045)/(1+0.095)^5+'DCF Model'!C27-'DCF Model'!C26-'DCF Model'!C73-'DCF Model'!C74)/'DCF Model'!C24 -> 41.338564 | F11: =('DCF Model'!C61/(1+0.105)^1+'DCF Model'!D61/(1+0.105)^2+'DCF Model'!E61/(1+0.105)^3+'DCF Model'!F61/(1+0.105)^4+'DCF Model'!G61/(1+0.105)^5+'DCF Model'!G61*(1+0.045)/(0.105-0.045)/(1+0.105)^5+'DCF Model'!C27-'DCF Model'!C26-'DCF Model'!C73-'DCF Model'!C74)/'DCF Model'!C24 -> 34.696123 | G11: =('DCF Model'!C61/(1+0.115)^1+'DCF Model'!D61/(1+0.115)^2+'DCF Model'!E61/(1+0.115)^3+'DCF Model'!F61/(1+0.115)^4+'DCF Model'!G61/(1+0.115)^5+'DCF Model'!G61*(1+0.045)/(0.115-0.045)/(1+0.115)^5+'DCF Model'!C27-'DCF Model'!C26-'DCF Model'!C73-'DCF Model'!C74)/'DCF Model'!C24 -> 29.964599 | H11: =('DCF Model'!C61/(1+0.125)^1+'DCF Model'!D61/(1+0.125)^2+'DCF Model'!E61/(1+0.125)^3+'DCF Model'!F61/(1+0.125)^4+'DCF Model'!G61/(1+0.125)^5+'DCF Model'!G61*(1+0.045)/(0.125-0.045)/(1+0.125)^5+'DCF Model'!C27-'DCF Model'!C26-'DCF Model'!C73-'DCF Model'!C74)/'DCF Model'!C24 -> 26.426871
B12: 0.05 | C12: =('DCF Model'!C61/(1+0.075)^1+'DCF Model'!D61/(1+0.075)^2+'DCF Model'!E61/(1+0.075)^3+'DCF Model'!F61/(1+0.075)^4+'DCF Model'!G61/(1+0.075)^5+'DCF Model'!G61*(1+0.05)/(0.075-0.05)/(1+0.075)^5+'DCF Model'!C27-'DCF Model'!C26-'DCF Model'!C73-'DCF Model'!C74)/'DCF Model'!C24 -> 79.960435 | D12: =('DCF Model'!C61/(1+0.085)^1+'DCF Model'!D61/(1+0.085)^2+'DCF Model'!E61/(1+0.085)^3+'DCF Model'!F61/(1+0.085)^4+'DCF Model'!G61/(1+0.085)^5+'DCF Model'!G61*(1+0.05)/(0.085-0.05)/(1+0.085)^5+'DCF Model'!C27-'DCF Model'!C26-'DCF Model'!C73-'DCF Model'!C74)/'DCF Model'!C24 -> 57.497574 | E12: =('DCF Model'!C61/(1+0.095)^1+'DCF Model'!D61/(1+0.095)^2+'DCF Model'!E61/(1+0.095)^3+'DCF Model'!F61/(1+0.095)^4+'DCF Model'!G61/(1+0.095)^5+'DCF Model'!G61*(1+0.05)/(0.095-0.05)/(1+0.095)^5+'DCF Model'!C27-'DCF Model'!C26-'DCF Model'!C73-'DCF Model'!C74)/'DCF Model'!C24 -> 45.040149 | F12: =('DCF Model'!C61/(1+0.105)^1+'DCF Model'!D61/(1+0.105)^2+'DCF Model'!E61/(1+0.105)^3+'DCF Model'!F61/(1+0.105)^4+'DCF Model'!G61/(1+0.105)^5+'DCF Model'!G61*(1+0.05)/(0.105-0.05)/(1+0.105)^5+'DCF Model'!C27-'DCF Model'!C26-'DCF Model'!C73-'DCF Model'!C74)/'DCF Model'!C24 -> 37.129804 | G12: =('DCF Model'!C61/(1+0.115)^1+'DCF Model'!D61/(1+0.115)^2+'DCF Model'!E61/(1+0.115)^3+'DCF Model'!F61/(1+0.115)^4+'DCF Model'!G61/(1+0.115)^5+'DCF Model'!G61*(1+0.05)/(0.115-0.05)/(1+0.115)^5+'DCF Model'!C27-'DCF Model'!C26-'DCF Model'!C73-'DCF Model'!C74)/'DCF Model'!C24 -> 31.667212 | H12: =('DCF Model'!C61/(1+0.125)^1+'DCF Model'!D61/(1+0.125)^2+'DCF Model'!E61/(1+0.125)^3+'DCF Model'!F61/(1+0.125)^4+'DCF Model'!G61/(1+0.125)^5+'DCF Model'!G61*(1+0.05)/(0.125-0.05)/(1+0.125)^5+'DCF Model'!C27-'DCF Model'!C26-'DCF Model'!C73-'DCF Model'!C74)/'DCF Model'!C24 -> 27.67272
B14: KEY: Gold cell = Base Case (WACC 9.73%, TG 4.0%) | Current Market Price = $87.20
B15: Current Share Price (Market) | C15: 87.2
B16: Implied Upside at Base Case | C16: =E10/C15-1 -> -0.56066521
B18: TABLE 2 — SENSITIVITY INTERPRETATION
B19: Cells showing > $87.20 | C19: Scenarios where model implies stock is UNDERVALUED (BUY territory)
B20: Cells showing $50–$87 | C20: Scenarios where model implies MODERATE downside risk
B21: Cells showing < $50 | C21: Scenarios where model implies SIGNIFICANT SELL (base case falls here)
B22: Gold cell | C22: Our base case assumption (WACC 9.73%, Terminal Growth 4.0%)

Sheet Football Field
B1: FOOTBALL FIELD VALUATION SUMMARY | Shopify Inc. (SHOP)
B2: Comparison of implied share price ranges across three valuation methodologies
B4: VALUATION RANGE SUMMARY
B5: Methodology | C5: Low ($) | D5: High ($) | E5: Basis / Notes
B6: DCF — Bear Case | C6: 22 | D6: 35 | E6: WACC 11.5%, TG 2.5% — high discount rate scenario
B7: DCF — Base Case | C7: 38 | D7: 45 | E7: WACC 9.7%, TG 4.0% — our central estimate
B8: DCF — Bull Case | C8: 55 | D8: 72 | E8: WACC 8.0%, TG 5.0% — high growth, low discount
B9: Comparable Companies | C9: 38 | D9: 58 | E9: EV/NTM Revenue: 4.0x–6.5x peer range applied to SHOP NTM Rev
B10: Precedent Transactions | C10: 65 | D10: 110 | E10: EV/LTM Rev: 5x–14x transaction range — includes control premium
B11: 52-Week Trading Range | C11: 56 | D11: 99 | E11: Source: NYSE, SHOP 52-week range March 2026
B13: Current Market Price | C13: 87.2 | D13: NYSE, March 2026
B15: FOOTBALL FIELD CHART — Build in Excel using Insert → Bar Chart → Stacked Bar
B16: Step 1 | C16: Select columns B:D (Methodology, Low, High) from rows 6–11
B17: Step 2 | C17: Insert → Bar Chart → Stacked Horizontal Bar
B18: Step 3 | C18: Set 'Low' series fill to white (invisible) — creates the floating bar effect
B19: Step 4 | C19: Add a vertical line at $87.20 (current price) using secondary axis reference line
B20: Step 5 | C20: Label each bar with the methodology name and price range
B22: CHART DATA — Used by chart below
B23: Methodology | C23: Base (invisible) | D23: Range Width
B24: DCF — Bear Case | C24: 22 | D24: =D6-C6 -> 13
B25: DCF — Base Case | C25: 38 | D25: =D7-C7 -> 7
B26: DCF — Bull Case | C26: 55 | D26: =D8-C8 -> 17
B27: Comparable Companies | C27: 38 | D27: =D9-C9 -> 20
B28: Precedent Transactions | C28: 65 | D28: =D10-C10 -> 45
B29: 52-Week Trading Range | C29: 56 | D29: =D11-C11 -> 43

Sheet Inv. Thesis
B1: INVESTMENT THESIS | Shopify Inc. (SHOP) — SELL | Blended Target: ~$51
B2: Analyst: Vatsal Chavda | Honours BCom (Finance), Seneca Polytechnic | March 2026
B4: EXECUTIVE SUMMARY
B5: We initiate coverage of Shopify Inc. (NYSE: SHOP) with a SELL rating and a blended 12-month price target of $51, representing 42% downside from the current market price of $87.20. While Shopify is unquestionably the leading commerce operating system for SMEs globally — with $9.2B in FY2024 revenue, 19.5% FCF margin, and a deeply embedded payment and logistics ecosystem — the current valuation of ~11x NTM revenue already prices in a near-perfect execution scenario that leaves limited margin of safety for investors.
B8: THREE PILLARS OF THE INVESTMENT THESIS
B9: 1. Valuation Exceeds Fundamentals | C9: At 11x NTM Revenue, Shopify trades at a significant premium to its SaaS/commerce peers (median 4.4x). Our DCF base case (WACC 9.7%, TG 4.0%) implies an intrinsic value of ~$40, and even our bull case (WACC 8.0%, TG 5.0%) only supports ~$65–72. The stock requires sustained 20%+ revenue growth AND material margin expansion simultaneously to justify current prices — a scenario that historically materializes in fewer than 20% of high-growth SaaS companies at this stage.
B10: 2. FCF Margin Expansion is Priced In | C10: Shopify's FCF margin improved dramatically from near-zero in FY2022 to 19.5% in FY2024 — a genuine positive. However, consensus already models FCF margins of 22–25% by FY2027. The easy gains from cost restructuring (workforce reduction, Deliverr exit) are behind us. Further expansion requires Shopify Payments take rate growth, which faces competition from Stripe and PayPal, and Shopify Capital scaling, which introduces credit risk in a potential recession environment.
B11: 3. M&A Risk — Klaviyo Acquisition Dilutive | C11: The proposed acquisition of Klaviyo at $8.4B (10.4x EV/Revenue) is strategically logical — Klaviyo's CRM/email platform would deepen Shopify's merchant data flywheel — but is dilutive on a Year 1 basis under our base case (-16%). Integration risk is material: Shopify's last major acquisition (Deliverr, $2.1B, 2022) was divested within 18 months at a significant loss. The market will likely penalize near-term EPS dilution before synergies are realized.
B13: KEY RISKS TO OUR SELL THESIS (Upside Risks)
B14: GMV Acceleration | C14: Shopify's GMV grew 24% in FY2024 — if global e-commerce re-accelerates or Shopify gains disproportionate enterprise market share (Shopify Plus), revenue could meaningfully beat consensus and re-rate the stock higher.
B15: Payments Take Rate Expansion | C15: If Shopify Payments penetration reaches 65%+ (vs. ~58% today) and Shopify successfully launches financial products (Balance, Capital) internationally, blended take rates could expand faster than modelled — driving upside to our FCF estimates.
B16: AI Monetization | C16: Shopify Sidekick and AI-native storefront tools are early-stage but could create a new SaaS revenue layer. If monetized at $50–100/month per merchant across 2M+ merchants, this represents $1.2–2.4B in high-margin incremental revenue — not in our model.
B18: RE-RATING TRIGGER
B19: We would revisit our SELL rating and potentially upgrade to HOLD/BUY on a pullback to the $45–55 range (5.0–6.5x NTM Revenue), where the risk/reward becomes more balanced. Alternatively, if Shopify demonstrates FCF margins exceeding 22% for two consecutive quarters AND provides credible guidance for 25%+ sustained revenue growth, our DCF bull case of $65–72 would become the base case, warranting re-evaluation.
