Workbook

Sheet Cover
B1: HIGH-NET-WORTH CLIENT WEALTH PLAN — Comprehensive Financial Analysis
B2: Prepared by: Vatsal Chavda | Honours BCom Finance, Seneca Polytechnic | March 2026
B4: CLIENT PROFILE SUMMARY
B5: Client Name | C5: Robert & Sandra Mitchell (Simulated)
B6: Age | C6: 52 (Retirement Target: Age 65)
B7: Planning Horizon | C7: 13 Years (2026 → 2039)
B8: Investable Assets | C8: 2800000
B9: Annual Income | C9: 420000
B10: Risk Profile | C10: Balanced Growth (Moderate-Aggressive)
B11: Primary Goals | C11: Retirement income, estate transfer, tax minimization
B13: MODEL STRUCTURE — KEY OUTPUTS (Live Links)
B14: Projected Portfolio Value at Retirement (Age 65) | C14: =Portfolio!C35 -> 7710108.8
B15: Total Retirement Income (Annual) | C15: =RetirementPlan!C12 -> 402172.35
B16: Estimated Net Estate Value | C16: =EstatePlan!C18 -> 14049220
B17: Blended Portfolio Return (Net) | C17: =Assumptions!C39 -> 0.06375
B18: Total Tax Savings (RRSP + TFSA + Corp Structure) | C18: =TaxPlan!C22 -> 1018730.8
B19: Retirement Funding Ratio | C19: =RetirementPlan!C24 -> 1.0552963
B21: NAVIGATION
B22: → Sheets: Assumptions | Portfolio | Retirement Plan | Tax Plan | Estate Plan | Summary

Sheet Assumptions
B1: MODEL ASSUMPTIONS — All Inputs in Yellow | Blue = Hardcoded | Green = Linked
B2: CLIENT INPUTS
B3: Current Age | C3: 52 | D3: Client profile
B4: Retirement Age | C4: 65 | D4: Target retirement
B5: Planning Horizon (Years) | C5: =C4-C3 -> 13 | D5: Derived: retirement age minus current age
B6: Current Investable Assets ($) | C6: 2800000 | D6: Client-provided figure
B7: Annual Gross Income ($) | C7: 420000 | D7: T4 + corporate income
B8: Annual Living Expenses ($) | C8: 180000 | D8: Client budget estimate
B9: Annual Savings / New Contributions ($) | C9: =C7-C8-C10 -> 46128 | D9: Derived: Income less expenses and tax
B10: Estimated Annual Income Tax ($) | C10: =C7*C14 -> 193872 | D10: Derived: Gross income × combined marginal rate (simplified)
B11: TAX INPUTS
B12: Federal Marginal Tax Rate | C12: 0.33 | D12: CRA 2025: $246,752+ bracket = 33%
B13: Ontario Provincial Tax Rate | C13: 0.1316 | D13: Ontario 2025: $220,000+ = 13.16%
B14: Combined Marginal Tax Rate | C14: =C12+C13 -> 0.4616 | D14: Derived: Federal + Provincial
B15: Capital Gains Inclusion Rate | C15: 0.5 | D15: CRA 2025: 50% inclusion on personal gains
B16: RRSP Annual Contribution Limit ($) | C16: 31560 | D16: CRA 2025: 18% of earned income max $31,560
B17: TFSA Annual Contribution Limit ($) | C17: 7000 | D17: CRA 2025 annual limit
B18: Corporate Tax Rate (SBD) | C18: 0.125 | D18: Ontario 2025 small business rate 12.5%
B20: PORTFOLIO & RETURN ASSUMPTIONS
B21: Equities Allocation (%) | C21: 0.45 | D21: Balanced growth for 52-yr HNW client
B22: Fixed Income Allocation (%) | C22: 0.25 | D22: Capital preservation component
B23: Alternative Investments (%) | C23: 0.2 | D23: Private equity, real assets, hedge funds
B24: Cash & Equivalents (%) | C24: 0.1 | D24: Liquidity buffer
B25: Equities Expected Return (Gross) | C25: 0.085 | D25: Historical TSX/S&P blended 10yr avg
B26: Fixed Income Expected Return (Gross) | C26: 0.042 | D26: Government + IG corporate bond avg 2025
B27: Alternatives Expected Return (Gross) | C27: 0.095 | D27: Industry benchmark — alternative investments avg (est.)
B28: Cash Expected Return (Gross) | C28: 0.045 | D28: HISA / T-Bill rate 2025
B29: Management Expense Ratio (MER) | C29: 0.0085 | D29: Typical wealth management MER estimate
B30: Inflation Rate | C30: 0.025 | D30: Bank of Canada 2% target + buffer
B32: BLENDED RETURN CALCULATION
B33: Equities Contribution | C33: =C21*C25 -> 0.03825 | D33: Allocation × Return
B34: Fixed Income Contribution | C34: =C22*C26 -> 0.0105 | D34: Allocation × Return
B35: Alternatives Contribution | C35: =C23*C27 -> 0.019 | D35: Allocation × Return
B36: Cash Contribution | C36: =C24*C28 -> 0.0045 | D36: Allocation × Return
B37: Gross Blended Return | C37: =C33+C34+C35+C36 -> 0.07225 | D37: Sum of weighted returns
B38: Less: MER | C38: =-C29 -> -0.0085 | D38: Management fee drag
B39: Net Blended Return (After Fees) | C39: =C37+C38 -> 0.06375
B41: ESTATE & INSURANCE INPUTS
B42: Life Insurance Coverage ($) | C42: 1200000 | D42: Face value — term/permanent blend
B43: Annual Insurance Premium ($) | C43: 18500 | D43: Estimated for age 52, non-smoker
...

Sheet Portfolio
B1: PORTFOLIO PROJECTION — 13-Year Horizon (Age 52 to 65) | All Values in CAD ($)
B3: Item | C3: 2026 Age 52 | D3: 2027 Age 53 | E3: 2028 Age 54 | F3: 2029 Age 55 | G3: 2030 Age 56 | H3: 2031 Age 57 | I3: 2032 Age 58 | J3: 2033 Age 59 | K3: 2034 Age 60 | L3: 2035 Age 61 | M3: 2036 Age 62 | N3: 2037 Age 63 | O3: 2038 Age 64 | P3: 2039 Age 65
B4: PORTFOLIO VALUE PROGRESSION
B5: Opening Portfolio Value ($) | C5: =Assumptions!C6 -> 2800000 | D5: =C9 -> 3027568.7 | E5: =D9 -> 3269644.8 | F5: =E9 -> 3527153.3 | G5: =F9 -> 3801078 | H5: =G9 -> 4092465.4 | I5: =H9 -> 4402428.7 | J5: =I9 -> 4732152.2 | K5: =J9 -> 5082895.6 | ... P5: =O9 -> 7201917.8
B6: New Contributions ($) | C6: =Assumptions!C9 -> 46128 | D6: =Assumptions!C9 -> 46128 | E6: =Assumptions!C9 -> 46128 | F6: =Assumptions!C9 -> 46128 | G6: =Assumptions!C9 -> 46128 | H6: =Assumptions!C9 -> 46128 | I6: =Assumptions!C9 -> 46128 | J6: =Assumptions!C9 -> 46128 | K6: =Assumptions!C9 -> 46128 | L6: =Assumptions!C9 -> 46128 | M6: =Assumptions!C9 -> 46128 | N6: =Assumptions!C9 -> 46128 | O6: =Assumptions!C9 -> 46128 | P6: =Assumptions!C9 -> 46128
B7: Investment Return ($) | C7: =(C5+C6)*Assumptions!C37 -> 205632.75 | D7: =(D5+D6)*Assumptions!C37 -> 222074.58 | E7: =(E5+E6)*Assumptions!C37 -> 239564.59 | F7: =(F5+F6)*Assumptions!C37 -> 258169.58 | G7: =(G5+G6)*Assumptions!C37 -> 277960.64 | H7: =(H5+H6)*Assumptions!C37 -> 299013.37 | I7: =(I5+I6)*Assumptions!C37 -> 321408.22 | J7: =(J5+J6)*Assumptions!C37 -> 345230.75 | K7: =(K5+K6)*Assumptions!C37 -> 370571.95 | L7: =(L5+L6)*Assumptions!C37 -> 397528.66 | M7: =(M5+M6)*Assumptions!C37 -> 426203.87 | N7: =(N5+N6)*Assumptions!C37 -> 456707.11 | O7: =(O5+O6)*Assumptions!C37 -> 489154.94 | P7: =(P5+P6)*Assumptions!C37 -> 523671.31
B8: Less: Fees (MER) ($) | C8: =-(C5+C6)*Assumptions!C29 -> -24192.088 | D8: =-(D5+D6)*Assumptions!C29 -> -26126.422 | E8: =-(E5+E6)*Assumptions!C29 -> -28184.069 | F8: =-(F5+F6)*Assumptions!C29 -> -30372.891 | G8: =-(G5+G6)*Assumptions!C29 -> -32701.251 | H8: =-(H5+H6)*Assumptions!C29 -> -35178.044 | I8: =-(I5+I6)*Assumptions!C29 -> -37812.732 | J8: =-(J5+J6)*Assumptions!C29 -> -40615.382 | K8: =-(K5+K6)*Assumptions!C29 -> -43596.701 | L8: =-(L5+L6)*Assumptions!C29 -> -46768.078 | M8: =-(M5+M6)*Assumptions!C29 -> -50141.631 | N8: =-(N5+N6)*Assumptions!C29 -> -53730.248 | O8: =-(O5+O6)*Assumptions!C29 -> -57547.64 | P8: =-(P5+P6)*Assumptions!C29 -> -61608.39
B9: Closing Portfolio Value ($) | C9: =C5+C6+C7+C8 -> 3027568.7 | D9: =D5+D6+D7+D8 -> 3269644.8 | E9: =E5+E6+E7+E8 -> 3527153.3 | F9: =F5+F6+F7+F8 -> 3801078 | G9: =G5+G6+G7+G8 -> 4092465.4 | H9: =H5+H6+H7+H8 -> 4402428.7 | I9: =I5+I6+I7+I8 -> 4732152.2 | J9: =J5+J6+J7+J8 -> 5082895.6 | ... P9: =P5+P6+P7+P8 -> 7710108.8
B11: ASSET ALLOCATION BREAKDOWN (Based on Closing Portfolio Value)
B12: Equities (45%) | C12: =C9*Assumptions!C21 -> 1362405.9 | D12: =D9*Assumptions!C21 -> 1471340.2 | E12: =E9*Assumptions!C21 -> 1587219 | F12: =F9*Assumptions!C21 -> 1710485.1 | G12: =G9*Assumptions!C21 -> 1841609.4 | H12: =H9*Assumptions!C21 -> 1981092.9 | I12: =I9*Assumptions!C21 -> 2129468.5 | J12: =J9*Assumptions!C21 -> 2287303 | K12: =K9*Assumptions!C21 -> 2455199.5 | L12: =L9*Assumptions!C21 -> 2633799.3 | M12: =M9*Assumptions!C21 -> 2823785 | N12: =N9*Assumptions!C21 -> 3025882.1 | O12: =O9*Assumptions!C21 -> 3240863 | P12: =P9*Assumptions!C21 -> 3469548.9
B13: Fixed Income (25%) | C13: =C9*Assumptions!C22 -> 756892.17 | D13: =D9*Assumptions!C22 -> 817411.21 | E13: =E9*Assumptions!C22 -> 881788.33 | F13: =F9*Assumptions!C22 -> 950269.51 | G13: =G9*Assumptions!C22 -> 1023116.4 | H13: =H9*Assumptions!C22 -> 1100607.2 | I13: =I9*Assumptions!C22 -> 1183038.1 | J13: =J9*Assumptions!C22 -> 1270723.9 | K13: =K9*Assumptions!C22 -> 1363999.7 | L13: =L9*Assumptions!C22 -> 1463221.9 | M13: =M9*Assumptions!C22 -> 1568769.4 | N13: =N9*Assumptions!C22 -> 1681045.6 | O13: =O9*Assumptions!C22 -> 1800479.5 | P13: =P9*Assumptions!C22 -> 1927527.2
B14: Alternatives (20%) | C14: =C9*Assumptions!C23 -> 605513.73 | D14: =D9*Assumptions!C23 -> 653928.96 | E14: =E9*Assumptions!C23 -> 705430.67 | F14: =F9*Assumptions!C23 -> 760215.6 | G14: =G9*Assumptions!C23 -> 818493.08 | H14: =H9*Assumptions!C23 -> 880485.75 | I14: =I9*Assumptions!C23 -> 946430.45 | J14: =J9*Assumptions!C23 -> 1016579.1 | K14: =K9*Assumptions!C23 -> 1091199.8 | L14: =L9*Assumptions!C23 -> 1170577.5 | M14: =M9*Assumptions!C23 -> 1255015.5 | N14: =N9*Assumptions!C23 -> 1344836.5 | O14: =O9*Assumptions!C23 -> 1440383.6 | P14: =P9*Assumptions!C23 -> 1542021.8
B15: Cash & Equivalents (10%) | C15: =C9*Assumptions!C24 -> 302756.87 | D15: =D9*Assumptions!C24 -> 326964.48 | E15: =E9*Assumptions!C24 -> 352715.33 | F15: =F9*Assumptions!C24 -> 380107.8 | G15: =G9*Assumptions!C24 -> 409246.54 | H15: =H9*Assumptions!C24 -> 440242.87 | I15: =I9*Assumptions!C24 -> 473215.22 | J15: =J9*Assumptions!C24 -> 508289.56 | K15: =K9*Assumptions!C24 -> 545599.88 | L15: =L9*Assumptions!C24 -> 585288.74 | M15: =M9*Assumptions!C24 -> 627507.77 | N15: =N9*Assumptions!C24 -> 672418.25 | O15: =O9*Assumptions!C24 -> 720191.78 | P15: =P9*Assumptions!C24 -> 771010.88
B17: REAL VALUE (Inflation-Adjusted at 2.5%)
B18: Real Portfolio Value ($) | C18: =C9/(1+Assumptions!C30)^1 -> 2953725.5 | D18: =D9/(1+Assumptions!C30)^2 -> 3112095 | E18: =E9/(1+Assumptions!C30)^3 -> 3275312.5 | F18: =F9/(1+Assumptions!C30)^4 -> 3443589.1 | G18: =G9/(1+Assumptions!C30)^5 -> 3617143.1 | H18: =H9/(1+Assumptions!C30)^6 -> 3796200.5 | I18: =I9/(1+Assumptions!C30)^7 -> 3980995.2 | J18: =J9/(1+Assumptions!C30)^8 -> 4171769.1 | K18: =K9/(1+Assumptions!C30)^9 -> 4368773 | L18: =L9/(1+Assumptions!C30)^10 -> 4572266.3 | M18: =M9/(1+Assumptions!C30)^11 -> 4782517.7 | N18: =N9/(1+Assumptions!C30)^12 -> 4999805.5 | O18: =O9/(1+Assumptions!C30)^13 -> 5224417.9 | P18: =P9/(1+Assumptions!C30)^14 -> 5456653.6
B20: ANNUAL RETURN METRICS
B21: Annual Net Return ($) | C21: =C7+C8 -> 181440.66 | D21: =D7+D8 -> 195948.16 | E21: =E7+E8 -> 211380.52 | F21: =F7+F8 -> 227796.69 | G21: =G7+G8 -> 245259.38 | H21: =H7+H8 -> 263835.33 | I21: =I7+I8 -> 283595.49 | J21: =J7+J8 -> 304615.36 | ... P21: =P7+P8 -> 462062.92
B22: Annual Net Return (%) | C22: =C21/C5 -> 0.064800236 | D22: =D21/D5 -> 0.064721294 | E22: =E21/E5 -> 0.064649382 | F22: =F21/F5 -> 0.06458372 | G22: =G21/G5 -> 0.064523638 | H22: =H21/H5 -> 0.064468555 | I22: =I21/I5 -> 0.064417963 | J22: =J21/J5 -> 0.064371421 | ... P22: =P21/P5 -> 0.064158316
B23: Cumulative Return ($) | C23: =C21 -> 181440.66 | D23: =C23+D21 -> 377388.82 | E23: =D23+E21 -> 588769.34 | F23: =E23+F21 -> 816566.02 | G23: =F23+G21 -> 1061825.4 | H23: =G23+H21 -> 1325660.7 | I23: =H23+I21 -> 1609256.2 | J23: =I23+J21 -> 1913871.6 | K23: =J23+K21 -> 2240846.8 | ... P23: =O23+P21 -> 4264316.8
B25: KEY PORTFOLIO STATISTICS
B26: Starting Value (2026) | C26: =C5 -> 2800000
B27: Ending Value (2039) | C27: =P9 -> 7710108.8
B28: Total Contributions | C28: =SUM(C6:P6) -> 645792
B29: Total Investment Return | C29: =SUM(C7:P7) -> 4832892.3
B30: Total Fees Paid | C30: =SUM(C8:P8) -> -568575.57
B31: Net Portfolio Growth | C31: =P9-C5 -> 4910108.8
B32: CAGR (Net) | C32: =(P9/C5)^(1/14)-1 -> 0.075032528
B33: Real Value at Retirement | C33: =P18 -> 5456653.6
B35: Retirement Portfolio Value (Cover Link) | C35: =P9 -> 7710108.8

Sheet RetirementPlan
B1: RETIREMENT INCOME PLAN — Target Age 65 | Projected to Age 90 (25-Year Drawdown)
B3: RETIREMENT INCOME SOURCES
C4: Annual ($) | D4: Notes
B5: Portfolio Drawdown (4% SWR) | C5: =Portfolio!P9*0.04 -> 308404.35 | D5: 4% Safe Withdrawal Rate on retirement portfolio
B6: CPP Benefit (Age 65) | C6: 24900 | D6: 2025 max CPP: $1,306.57/mo × 12 = $15,679 (est. ~$24,900 w/ enhancement)
B7: OAS Benefit (Age 65) | C7: 8618 | D7: 2025 OAS: $718.33/mo × 12 = $8,618
B8: RRSP/RRIF Annual Drawdown | C8: =Assumptions!C44*0.05 -> 19250 | D8: 5% annual drawdown from RRIF at retirement
B9: TFSA Annual Withdrawal | C9: =Assumptions!C45*0.04 -> 3800 | D9: 4% withdrawal from TFSA (tax-free)
B10: Corporate Holdco Distribution | C10: =Assumptions!C48*0.06 -> 37200 | D10: 6% annual dividend from Holdco
B11: Rental / Other Income | C11: 0 | D11: Not included — conservative assumption
B12: Total Annual Retirement Income | C12: =SUM(C5:C11) -> 402172.35 | D12: Sum of all retirement income streams
B14: RETIREMENT EXPENSES & ADEQUACY
C15: Annual ($) | D15: Notes
B16: Estimated Living Expenses (Retirement) | C16: =Assumptions!C8*0.75 -> 135000 | D16: 75% of pre-retirement expenses (industry rule)
B17: Inflation-Adjusted Expenses (Yr 1) | C17: =C16*(1+Assumptions!C30)^Assumptions!C5 -> 186098.99 | D17: Adjusted for inflation over planning horizon
B18: Healthcare & Long-Term Care Reserve | C18: 35000 | D18: Annual provision for healthcare costs
B19: Travel & Lifestyle Budget | C19: 25000 | D19: Discretionary spending estimate
B20: Total Annual Retirement Expenses | C20: =SUM(C16:C19) -> 381098.99
B22: RETIREMENT ADEQUACY METRICS
B23: Annual Surplus / (Deficit) | C23: =C12-C20 -> 21073.359
B24: Funding Ratio (Income / Exp.) | C24: =C12/C20 -> 1.0552963
B25: Years Portfolio Sustains (Est.) | C25: =Portfolio!P9/C20 -> 20.231249
B26: Replacement Rate | C26: =C12/Assumptions!C7 -> 0.95755321

Sheet TaxPlan
B1: TAX OPTIMIZATION PLAN — Annual & Lifetime Strategies
B3: ANNUAL TAX SAVINGS ANALYSIS
C4: Annual Saving ($) | D4: Strategy Detail
B5: RRSP Contribution Tax Deduction | C5: =Assumptions!C16*Assumptions!C14 -> 14568.096 | D5: Max RRSP $31,560 × 46.16% marginal rate = ~$14,572 tax saved
B6: TFSA Tax-Free Compounding (Annual Benefit) | C6: =Assumptions!C17*Assumptions!C37*Assumptions!C14 -> 233.4542 | D6: TFSA return shielded from tax at marginal rate
B7: Corporate Holdco Income Splitting | C7: =Assumptions!C48*0.06*(Assumptions!C14-Assumptions!C18) -> 12521.52 | D7: Dividend at corp rate vs. personal rate differential
B8: Charitable Donation Tax Credit | C8: =Assumptions!C47*0.29 -> 4350 | D8: Federal 29% credit on donations above $200 threshold
B9: Capital Gains Advantage vs. Income | C9: =Assumptions!C6*Assumptions!C37*Assumptions!C14*(1-Assumptions!C15) -> 46690.84 | D9: Tax saving from 50% inclusion vs. full income tax
B10: Total Annual Tax Savings | C10: =SUM(C5:C9) -> 78363.91
B12: RRSP PROJECTION TO RETIREMENT
C13: Value ($) | D13: Notes
B14: Current RRSP Balance | C14: =Assumptions!C44 -> 385000 | D14: From Assumptions
B15: Annual Contribution | C15: =Assumptions!C16 -> 31560 | D15: Max annual contribution
B16: Years to Retirement | C16: =Assumptions!C5 -> 13 | D16: Planning horizon
B17: Projected RRSP at Retirement | C17: =C14*(1+Assumptions!C37)^C16+C15*((1+Assumptions!C37)^C16-1)/Assumptions!C37 -> 1598460.9 | D17: FV of existing balance + FV of annual contributions
B18: Estimated RRIF Annual Withdrawal | C18: =C17*0.05 -> 79923.044 | D18: 5% drawdown rate at retirement
B19: Tax on RRIF Withdrawal | C19: =C18*Assumptions!C14 -> 36892.477 | D19: Marginal rate applied to RRIF income
B21: LIFETIME TAX SAVINGS SUMMARY
B22: Total Lifetime Tax Savings (PV over 13 yrs) | C22: =C10*Assumptions!C5 -> 1018730.8 | D22: Annual savings × planning horizon (simplified lifetime estimate)

Sheet EstatePlan
B1: ESTATE PLAN — Net Estate Value & Wealth Transfer Strategy
B3: GROSS ESTATE VALUE AT RETIREMENT
C4: Value ($) | D4: Source / Notes
B5: Projected Investment Portfolio | C5: =Portfolio!P9 -> 7710108.8 | D5: From Portfolio sheet — retirement value
B6: Projected RRSP/RRIF Balance | C6: =TaxPlan!C17 -> 1598460.9 | D6: From Tax Plan — RRSP projection
B7: TFSA Balance (Projected) | C7: =Assumptions!C45*(1+Assumptions!C37)^Assumptions!C5+Assumptions!C17*((1+Assumptions!C37)^Assumptions!C5-1)/Assumptions!C37 -> 378330.76 | D7: FV of TFSA
B8: Primary Residence | C8: =Assumptions!C46*(1+Assumptions!C30)^Assumptions!C5 -> 2550245.4 | D8: Inflation-adjusted property value
B9: Corporate Holdco (Net) | C9: =Assumptions!C48*(1+Assumptions!C18)^Assumptions!C5 -> 2866648.7 | D9: Holdco grown at corporate rate
B10: Life Insurance Death Benefit | C10: =Assumptions!C42 -> 1200000 | D10: Face value policy payout
B11: Gross Estate Value | C11: =SUM(C5:C10) -> 16303795
B13: ESTATE LIABILITIES & TAX ON DEATH
B14: Deemed Disposition Tax (RRSP/RRIF) | C14: =TaxPlan!C17*Assumptions!C14 -> 737849.54 | D14: RRIF fully taxable at death at marginal rate
B15: Capital Gains Tax on Portfolio | C15: =Portfolio!P9*Assumptions!C15*Assumptions!C12 -> 1272167.9 | D15: 50% inclusion × federal rate on gains
B16: Probate Fees (Ontario, est.) | C16: =C11*0.015 -> 244556.92 | D16: ~1.5% of estate value in Ontario
B17: Outstanding Liabilities | C17: 0 | D17: Assumed debt-free at retirement
B18: Net Estate Value to Beneficiaries | C18: =C11-SUM(C14:C17) -> 14049220
B20: WEALTH TRANSFER VEHICLES
B21: Vehicle | C21: Status | D21: Rationale
B22: Testamentary Trust | C22: Recommended | D22: Splits income among beneficiaries; reduces tax on estate income
B23: Spousal RRSP Rollover | C23: Recommended | D23: Tax-deferred transfer to surviving spouse at death
B24: Beneficiary Designation (TFSA/RRSP) | C24: In Place | D24: Avoids probate; direct transfer to named beneficiary
B25: Charitable Remainder Trust | C25: Consider | D25: Ongoing charitable giving + income stream to client
B26: Holding Company Estate Freeze | C26: Recommended | D26: Lock in current Holdco value; future growth to children
B27: Life Insurance (Tax-Free Payout) | C27: In Place | D27: $1.2M death benefit passes tax-free to beneficiaries

Sheet Summary
B1: WEALTH PLAN SUMMARY DASHBOARD — Robert & Sandra Mitchell | March 2026
B3: PORTFOLIO & GROWTH
B4: Metric | C4: Value | D4: Benchmark / Note
B5: Starting Portfolio Value (2026) | C5: =Assumptions!C6 -> 2800000 | D5: Client baseline
B6: Projected Portfolio at Retirement | C6: =Portfolio!P9 -> 7710108.8 | D6: Target: $5M+
B7: Real Value at Retirement (2039 $) | C7: =Portfolio!P18 -> 5456653.6 | D7: Purchasing power adjusted
B8: Total Contributions (13 Years) | C8: =SUM(Portfolio!C6:P6) -> 645792 | D8: Regular annual savings
B9: Total Investment Return | C9: =SUM(Portfolio!C7:P7) -> 4832892.3 | D9: Net of MER
B10: Portfolio CAGR (Net of Fees) | C10: =Portfolio!C32 -> 0.075032528 | D10: Target: 6.0%+
B11: Blended Net Return (Annual) | C11: =Assumptions!C39 -> 0.06375 | D11: Weighted allocation return
B13: RETIREMENT INCOME ADEQUACY
B14: Total Annual Retirement Income | C14: =RetirementPlan!C12 -> 402172.35
B15: Total Annual Retirement Expenses | C15: =RetirementPlan!C20 -> 381098.99
B16: Annual Surplus / (Deficit) | C16: =RetirementPlan!C23 -> 21073.359
B17: Funding Ratio | C17: =RetirementPlan!C24 -> 1.0552963
B18: Income Replacement Rate | C18: =RetirementPlan!C26 -> 0.95755321
B19: Portfolio Sustains (Years Est.) | C19: =RetirementPlan!C25 -> 20.231249
B21: TAX & ESTATE SUMMARY
B22: Annual Tax Savings (All Strategies) | C22: =TaxPlan!C10 -> 78363.91
B23: Lifetime Tax Savings (Est.) | C23: =TaxPlan!C22 -> 1018730.8
B24: Projected RRSP Value at Retirement | C24: =TaxPlan!C17 -> 1598460.9
B25: Gross Estate Value | C25: =EstatePlan!C11 -> 16303795
B26: Net Estate to Beneficiaries | C26: =EstatePlan!C18 -> 14049220
B27: Life Insurance Coverage | C27: =Assumptions!C42 -> 1200000
B28: ADVISOR RECOMMENDATION
B29: Based on this comprehensive analysis, the Mitchell household is on track to achieve a fully-funded retirement with a projected funding ratio above 100%, a net estate exceeding $7M, and annual tax savings of over $50,000 through disciplined RRSP maximization, TFSA utilization, corporate structuring, and charitable giving. The recommended multi-asset allocation (45% equities / 25% fixed income / 20% alternatives / 10% cash) is designed to generate a 6.2%+ blended net return while maintaining appropriate liquidity and downside protection consistent with a Balanced Growth risk profile.
